Workbook

Sheet 1.物調-封面
B25: 物件名稱 | T25: ='秘書-input'!B1 -> 西門黃金店面
B52: 地址
B57: ='秘書-input'!B3 -> 台北市萬華區 | O57: ='秘書-input'!C4 -> 成都路 | AN57: ='秘書-input'!D4 -> 92號

Sheet 2.物調-第1頁
Y1: 物件個案調查表 | AU1: ='秘書-input'!B2 -> 售
A6: 案名 | D6: ='秘書-input'!B1 -> 西門黃金店面 | Y6: 坪數 | AB6: ='秘書-input'!E46 -> 34.8359 | AL6: 坪 | AO6: 售價 | AR6: ='秘書-input'!B10 -> 7588 | AX6: 萬
A11: 路段: | I11: ='秘書-input'!B4 -> 台北市萬華區 | U11: ='秘書-input'!C4 -> 成都路
A14: 建物名稱: | I14: ='秘書-input'!B9 -> 無 | AB14: 建物 | AE14: ='秘書-input'!B39 -> 一層: | AL14: ='秘書-input'!E39 -> 12.92885 | AX14: 坪
A16: 建築完成日: | I16: ='秘書-input'!B11 -> 24015 | R16: 屋齡: | V16: ='秘書-input'!E11 -> 46.879452 | Z16: 年 | AE16: ='秘書-input'!B40 -> 二層: | AL16: ='秘書-input'!E40 -> 17.41795 | AX16: 坪
A18: 樓層: | I18: ='秘書-input'!B13 -> 地上共7層/地下0層;本建物在第1~2層 | AE18: ='秘書-input'!B41 -> 騎樓: | AL18: ='秘書-input'!E41 -> 4.4891 | AX18: 坪
A20: 格局: | I20: ='秘書-input'!B14 -> 0/2/2 | R20: 座向: | V20: ='秘書-input'!B15 | AE20: ='秘書-input'!B42 -> 其他: | AL20: ='秘書-input'!E42 -> 0 | AX20: 坪
A22: 主要用途 | I22: ='秘書-input'!B7 -> (空白) | AE22: ='秘書-input'!B43 -> 其他: | AL22: ='秘書-input'!E43 -> 0 | AX22: 坪
A24: 建築物管理費: | I24: ='秘書-input'!B20 | M24: 建物管理費約 | T24: ='秘書-input'!D20 | X24: 元/月 | AE24: ='秘書-input'!B44 -> 其他: | AL24: ='秘書-input'!E44 -> 0 | AX24: 坪
A26: 主要建材: | I26: ='秘書-input'!B12 -> 加強磚造 | AE26: ='秘書-input'!B45 -> 其他: | AL26: ='秘書-input'!E45 -> 0 | AX26: 坪
A28: 同層戶數: | I28: ='秘書-input'!B16 | M28: 戶 | AE28: 合計: | AL28: ='秘書-input'!E46 -> 34.8359 | AX28: 坪
A30: 邊間: | I30: ='秘書-input'!B17
AB31: 土地 | AE31: 地號 | AH31: ='秘書-input'!C30 -> 漢中段一小段776地號 | AR31: 基地面積: | AV31: ='秘書-input'!R30 -> 9.68 | AY31: 坪
A32: 中庭: | I32: ='秘書-input'!B18 | AE32: 分區 | AH32: ='秘書-input'!L30 -> 商四 | AR32: 持分: | AV32: ='秘書-input'!X30 -> 0.56466667 | AY32: 坪
A34: 電梯數: | I34: ='秘書-input'!B19 | AE34: 地號 | AH34: ='秘書-input'!C31 -> 漢中段一小段779地號 | AR34: 基地面積: | AV34: ='秘書-input'!R31 -> 297.9625 | AY34: 坪
AE35: 分區 | AH35: ='秘書-input'!L31 -> 商四 | AR35: 持分: | AV35: ='秘書-input'!X31 -> 17.281825 | AY35: 坪
A36: 瓦斯: | I36: ='秘書-input'!B24
AE37: 地號 | AH37: ='秘書-input'!C32 -> 漢中段一小段779-0001地號 | AR37: 基地面積: | AV37: ='秘書-input'!R32 -> 7.865 | AY37: 坪
A38: 警衛管理: | I38: ='秘書-input'!B21 | AE38: 分區 | AH38: ='秘書-input'!L32 -> 商四 | AR38: 持分: | AV38: ='秘書-input'!X32 -> 0.45617 | AY38: 坪
A40: 學區: | I40: ='秘書-input'!B22 -> 西門國小 龍山國中 | AE40: 地號 | AH40: ='秘書-input'!C33 -> 漢中段一小段780地號 | AR40: 基地面積: | AV40: ='秘書-input'!R33 -> 11.1925 | AY40: 坪
AE41: 分區 | AH41: ='秘書-input'!L33 -> 商四 | AR41: 持分: | AV41: ='秘書-input'!X33 -> 0.649165 | AY41: 坪
A42: ='秘書-input'!A25 -> 違建部份: | I42: ='秘書-input'!B25 -> 無
AE43: 地號 | AH43: ='秘書-input'!C34 -> 漢中段一小段780-0001地號 | AR43: 基地面積: | AV43: ='秘書-input'!R34 -> 62.315 | AY43: 坪
AE44: 分區 | AH44: ='秘書-input'!L34 -> 商四 | AR44: 持分: | AV44: ='秘書-input'!X34 -> 3.61427 | AY44: 坪
A45: 看屋方式: | I45: ='秘書-input'!B23 -> 請洽27713366 | AE45: 土地持分合計: | AR45: ='秘書-input'!X35 -> 22.00143 | AY45: 坪
A47: 特色 | D47: ='秘書-input'!B56 | AB47: 車位 | AE47: ='秘書-input'!B50 -> 有無車位: | AJ47: ='秘書-input'!C50 -> 無 | AN47: ='秘書-input'!D50 -> 車位價: | AR47: ='秘書-input'!E50 -> 無 | AW47: 萬
D49: ='秘書-input'!B57 | AE49: ='秘書-input'!B51 -> 可否另租: | AJ49: ='秘書-input'!C51 -> 無 | AN49: ='秘書-input'!D51 -> 租金約: | AR49: ='秘書-input'!E51 -> 無 | AW49: 元/月
D51: ='秘書-input'!B58 | AE51: ='秘書-input'!B52 -> 車位編號: | AJ51: ='秘書-input'!C52 -> 無 | AN51: ='秘書-input'!D52 -> 停車管理費: | AT51: ='秘書-input'!E52 -> 無 | AW51: 元/月
D53: ='秘書-input'!B59 | AE53: ='秘書-input'!B53 -> 使用方式: | AJ53: ='秘書-input'!C53 -> 無 | AN53: ='秘書-input'!D53 -> 停車方式: | AR53: ='秘書-input'!E53 -> 無
A55: 位置圖 | AB55: 格局圖
A75: 公司網址: http://www.hbhousing.com.tw/web/A313/

Sheet 3.物調-簽名
C7: 一、 銷 售 案 名: | N7: ='秘書-input'!B1 -> 西門黃金店面
C9: 二、 建 物 門 牌: | N9: ='秘書-input'!B4 -> 台北市萬華區 | V9: ='秘書-input'!C4 -> 成都路 | AK9: ='秘書-input'!D4 -> 92號
C11: 三、 製 作 單 位: | N11: ='秘書-input'!B5 -> 住商仁愛鳳翔加盟店 (願景不動產仲介股份有限公司)
C13: 四、 本說明書係依:台北市地政事務所核發之謄本為準,內容及附件如下:
C16: 主要內容 | Q16: 附件內容
E20: 產權調查篇 | S20: 土地權狀影本 | AJ20: 其他:
E22: 物件現況調查篇 | S22: 建物權狀影本 | AJ22: 地籍圖
E24: 位置與格間圖 | S24: 土地謄本 | AJ24: 建物平面圖
E26: 圖片說明書 | S26: 建物謄本 | AJ26: 海砂檢測報告
S28: 都市使用分區證明 | AJ28: 幅射檢測報告
S30: (或非都市土地編訂證明) *依主管機關核發證明資料或主管機關網路公布資料為準 | AJ30: 公寓大廈使用手冊
AJ32: 住戶規約
AJ34: 分管協議
S36: 建築改良物使用執照 | AJ36: 車位平面圖
AJ38: 都市計劃說明書
C42: 所有權人(賣方): | V42: (簽章) 住址:
C46: 買 方: | V46: (簽章) 住址:
C49: (簽訂買賣契約同時,由買方簽屬本欄)
C52: 經 紀 人: | V52: 營 業 員 :
C55: ※洽談買方客戶資料說明:買方簽定要約書、買方議價委託書、買賣訂金收款憑證者，均須同時要求於下列買方客戶簽名處簽名。
C59: 買方客戶已詳閱本不動產說明書，並確實瞭解其內容無誤
C62: 日期 | Q62: 買方客戶簽名 | AH62: 經紀人員

Sheet 4.物調-建物+車位
H8: 二、建物標示:
H14: 地 址: | N14: ='秘書-input'!B4 -> 台北市萬華區 | V14: ='秘書-input'!C4 -> 成都路 | AL14: ='秘書-input'!D4 -> 92號
H20: 建物 | N20: 建號: | S20: ='秘書-input'!C38 -> 漢中段一小段257.258建號
N22: ='秘書-input'!B39 -> 一層: | S22: ='秘書-input'!C39 -> 42.74 | Z22: 平方公尺，約 | AI22: =S22*0.3025 -> 12.92885 | AP22: 坪
N24: ='秘書-input'!B40 -> 二層: | S24: ='秘書-input'!C40 -> 57.58 | Z24: 平方公尺，約 | AI24: =S24*0.3025 -> 17.41795 | AP24: 坪
N26: ='秘書-input'!B41 -> 騎樓: | S26: ='秘書-input'!C41 -> 14.84 | Z26: 平方公尺，約 | AI26: =S26*0.3025 -> 4.4891 | AP26: 坪
N28: ='秘書-input'!B42 -> 其他: | S28: ='秘書-input'!C42 -> 0 | Z28: 平方公尺，約 | AI28: =S28*0.3025 -> 0 | AP28: 坪
N30: ='秘書-input'!B43 -> 其他: | S30: ='秘書-input'!C43 -> 0 | Z30: 平方公尺，約 | AI30: =S30*0.3025 -> 0 | AP30: 坪
N32: ='秘書-input'!B44 -> 其他: | S32: ='秘書-input'!C44 -> 0 | Z32: 平方公尺，約 | AI32: =S32*0.3025 -> 0 | AP32: 坪
N34: ='秘書-input'!B45 -> 其他: | S34: ='秘書-input'!C45 -> 0 | Z34: 平方公尺，約 | AI34: =S34*0.3025 -> 0 | AP34: 坪
N36: ='秘書-input'!B46 -> 合計 | S36: ='秘書-input'!C46 -> 115.16 | Z36: 平方公尺，約 | AI36: =S36*0.3025 -> 34.8359 | AP36: 坪
H40: 車位 | N40: 有無車位: | U40: ='秘書-input'!C50 -> 無 | Z40: 車位價: | AH40: ='秘書-input'!E50 -> 無 | AN40: 萬
N42: 可否另租: | U42: ='秘書-input'!C51 -> 無 | Z42: 租金約: | AH42: ='秘書-input'!E51 -> 無 | AN42: 元/月
N44: 車位編號: | U44: ='秘書-input'!C52 -> 無 | Z44: 停車管理費: | AH44: ='秘書-input'!E52 -> 無 | AN44: 元/月
N46: 使用方式: | U46: ='秘書-input'!C53 -> 無 | Z46: 停車方式: | AH46: ='秘書-input'!E53 -> 無
N48: 車位是否辦理獨立區分所有建物登記: | AL48: ='秘書-input'!E54 -> 無
H52: 他項權利 | N52: 權利種類 | V52: 順位 | AA52: 內容 | AG52: 權利人
N54: (依市政府 地政機關 登記謄本為準)
N56: (依市政府 地政機關 登記謄本為準)
N58: (依市政府 地政機關 登記謄本為準)
H62: 限制登記情形 | N62: ='秘書-input'!B48 -> 無
B68: * | C68: 上述各項面積合計係依地政機關登記簿謄本登載的面積平方公尺換算為坪所得。(1平方公尺=0.3025坪)，小數點第三位四捨五入取二位)。
C72: 建物登記用途請以地政機關辦法為準。
B73: *

Sheet 5.物調-土地
H5: 一、土地標示:
H7: 座落: | T7: ='秘書-input'!B3 -> 台北市萬華區 | AC7: ='秘書-input'!C30 -> 漢中段一小段776地號
H9: 基地面積 | T9: ='秘書-input'!E30 -> 32 | AA9: 平方公尺 | AG9: ，約 | AJ9: ='秘書-input'!R30 -> 9.68 | AP9: 坪
H11: 權利範圍 | T11: ='秘書-input'!H30 -> 1200 | AA11: 分之 | AG11: ='秘書-input'!J30 -> 70
H13: 持分面積 | T13: ='秘書-input'!U30 -> 1.8666667 | AA13: 平方公尺 | AG13: ，約 | AJ13: ='秘書-input'!X30 -> 0.56466667 | AP13: 坪
H15: 使用分區 | T15: ='秘書-input'!L30 -> 商四
H17: 建敝率 | T17: ='秘書-input'!N30 -> 0.75 | AA17: (依各縣市政府規定)
H19: 容積率 | T19: ='秘書-input'!P30 -> 8 | AA19: (依各縣市政府規定)
H21: 座落: | T21: ='秘書-input'!B3 -> 台北市萬華區 | AC21: ='秘書-input'!C31 -> 漢中段一小段779地號
H23: 基地面積 | T23: ='秘書-input'!E31 -> 985 | AA23: 平方公尺 | AG23: ，約 | AJ23: ='秘書-input'!R31 -> 297.9625 | AP23: 坪
H25: 權利範圍 | T25: ='秘書-input'!H31 -> 10000 | AA25: 分之 | AG25: ='秘書-input'!J31 -> 580
H27: 持分面積 | T27: ='秘書-input'!U31 -> 57.13 | AA27: 平方公尺 | AG27: ，約 | AJ27: ='秘書-input'!X31 -> 17.281825 | AP27: 坪
H29: 使用分區 | T29: ='秘書-input'!L31 -> 商四
H31: 建敝率 | T31: ='秘書-input'!N31 -> 0.75 | AA31: (依各縣市政府規定)
H33: 容積率 | T33: ='秘書-input'!P31 -> 8 | AA33: (依各縣市政府規定)
H35: 座落: | T35: ='秘書-input'!B3 -> 台北市萬華區 | AC35: ='秘書-input'!C32 -> 漢中段一小段779-0001地號
H37: 基地面積 | T37: ='秘書-input'!E32 -> 26 | AA37: 平方公尺 | AG37: ，約 | AJ37: ='秘書-input'!R32 -> 7.865 | AP37: 坪
H39: 權利範圍 | T39: ='秘書-input'!H32 -> 10000 | AA39: 分之 | AG39: ='秘書-input'!J32 -> 580
H41: 持分面積 | T41: ='秘書-input'!U32 -> 1.508 | AA41: 平方公尺 | AG41: ，約 | AJ41: ='秘書-input'!X32 -> 0.45617 | AP41: 坪
H43: 使用分區 | T43: ='秘書-input'!L32 -> 商四
H45: 建敝率 | T45: ='秘書-input'!N32 -> 0.75 | AA45: (依各縣市政府規定)
H47: 容積率 | T47: ='秘書-input'!P32 -> 8 | AA47: (依各縣市政府規定)
H49: 座落: | T49: ='秘書-input'!B3 -> 台北市萬華區 | AC49: ='秘書-input'!C33 -> 漢中段一小段780地號
H51: 基地面積 | T51: ='秘書-input'!E33 -> 37 | AA51: 平方公尺 | AG51: ，約 | AJ51: ='秘書-input'!R33 -> 11.1925 | AP51: 坪
H53: 權利範圍 | T53: ='秘書-input'!H33 -> 10000 | AA53: 分之 | AG53: ='秘書-input'!J33 -> 580
H55: 持分面積 | T55: ='秘書-input'!U33 -> 2.146 | AA55: 平方公尺 | AG55: ，約 | AJ55: ='秘書-input'!X33 -> 0.649165 | AP55: 坪
H57: 使用分區 | T57: ='秘書-input'!L33 -> 商四
H59: 建敝率 | T59: ='秘書-input'!N33 -> 0.75 | AA59: (依各縣市政府規定)
H61: 容積率 | T61: ='秘書-input'!P33 -> 8 | AA61: (依各縣市政府規定)
H63: 座落: | T63: ='秘書-input'!B3 -> 台北市萬華區 | AC63: ='秘書-input'!C34 -> 漢中段一小段780-0001地號
H65: 基地面積 | T65: ='秘書-input'!E34 -> 206 | AA65: 平方公尺 | AG65: ，約 | AJ65: ='秘書-input'!R34 -> 62.315 | AP65: 坪
H67: 權利範圍 | T67: ='秘書-input'!H34 -> 10000 | AA67: 分之 | AG67: ='秘書-input'!J34 -> 580
H69: 持分面積 | T69: ='秘書-input'!U34 -> 11.948 | AA69: 平方公尺 | AG69: ，約 | AJ69: ='秘書-input'!X34 -> 3.61427 | AP69: 坪
H71: 使用分區 | T71: ='秘書-input'!L34 -> 商四
H73: 建敝率 | T73: ='秘書-input'!N34 -> 0.75 | AA73: (依各縣市政府規定)
H75: 容積率 | T75: ='秘書-input'!P34 -> 8 | AA75: (依各縣市政府規定)
H77: 土地持份合計 | T77: ='秘書-input'!X35 -> 22.00143 | AL77: 坪
H79: 他項 權利 | P79: 權利種類 | W79: 順位 | AD79: 內容 | AK79: 權利人
P81: (依市政府 地政機關 登記謄本為準)
P83: (依市政府 地政機關 登記謄本為準)
...

Sheet 6.物調-其他交易條件
B8: 交易種類 | N8: ='秘書-input'!B2 -> 售
B13: 委託總價金 | N13: ='秘書-input'!B10 -> 7588 | AG13: 萬
B18: 付款方式 | N18: 期別 | AG18: 比例 | AO18: 金額
N21: 第一期款(簽約款)新台幣 | AG21: 0.2 | AO21: =$N$13*AG21 -> 1517.6 | AV21: 萬
N24: 第二期款(備證用印款)新台幣 | AG24: 0.1 | AO24: =$N$13*AG24 -> 758.8 | AV24: 萬
N27: 第三期款(完稅款)新台幣 | AG27: 0.2 | AO27: =$N$13*AG27 -> 1517.6 | AV27: 萬
N30: 第四期款(交屋款)新台幣 | Z30: (貸款不足應以現金乙次補足) | AG30: 0.5 | AO30: =$N$13*AG30 -> 3794 | AV30: 萬
B33: 應納稅額 規費項目 負擔方式 (皆以稅捐機關核定數額為準) | N33: 應納稅 | AG33: 規費
N36: 土地增值稅 | V36: 依核定 | AD36: 元 | AG36: 工程受益費 | AO36: 0 | AV36: 元
N39: 地價稅 | V39: 依核定 | AD39: 元 | AG39: 代書費 | AO39: 約18000 | AV39: 元
N42: 契稅 | V42: 依核定 | AD42: 元 | AG42: 登記規費 | AO42: 依核定 | AV42: 元
N45: 房屋稅 | V45: 依核定 | AD45: 元 | AG45: 水電、瓦斯 | AO45: 依分算 | AV45: 元
N48: 印花稅 | V48: 依核定 | AD48: 元 | AG48: 管理費 | AO48: 依分算 | AV48: 元
N51: 以上應納稅額及規費等負擔，均以買賣契約書之約定為準。
B54: 賣方附贈設備 | N54: 無。依固定物交屋
B57: 交屋情形 | N57: 立即
B60: 主要用途 | N60: ='秘書-input'!B7 -> (空白)
B63: 交通條件說明 | N63: ='秘書-input'!B26 -> 近捷運西門站
B66: 備註

Sheet 7.物調-相關費用
B3: ****************************** 賣 方 支 付 項 目 ************************************
B4: 1 | C4: 土地增值稅: ㄧ般稅率之稅費約: | K4: 元
C5: 自用優惠稅率之稅費: | K5: 元
C6: * | D6: 以上稅額會因過戶申報時點將影響長期持有期限之計算,故暫以本表列印日期為截止日,實際金額仍以稅捐機關核發稅單為準
C8: * | D8: 因各月物價指數波動會影響增值稅金額,若要收訂斡前須再確認
C9: * | D9: 每年1月公告現值調整,將影響增值稅金額,需重新計算
B10: 2 | C10: 工程受益費:簽約日前已開徵或已開徵未到期(含緩徵)者,由賣方負擔
B11: 3 | C11: 地價稅:依最近一年稅費概估 ㄧ般稅率之稅費約 | J11: 元
C12: 自用稅率之稅費約 | J12: 元,實際稅額以所核
C13: 發稅單為準,交屋日時依所有權人目前稅額按實際使用比例分算,若遇公告地價調整,另行計算
B14: 4 | C14: 房屋稅:委託人無法即時提供稅單資料,故無法概算(於交屋日依實際使用比例分算)
C15: 住家用按房屋現值 ＊ 1.2%
C16: 營業用按房屋現值 ＊ 3 %
B17: 5 | C17: 水、電、瓦斯費、管理費等雜項費用(於交屋日依實際使用比例分算)
B18: 6 | C18: 抵押權塗銷代書費:ㄧ順位1500元
B19: 7 | C19: 財產交易所得稅(併入綜合所得於每年申報所得稅時申報)
B20: 8 | C20: 仲介服務費:按實際成交價格的百分之四
B23: ****************************** 買 方 支 付 項 目 ************************************
B24: 1 | C24: 契 稅:委託人無法及時提供稅單資料,故無法概算
C25: 按核定契價＊ 6 %
B26: 2 | C26: 印花稅:委託人無法及時提供稅單資料,故無法概算
C27: 按[核定契價+(土地公告現值*面積*持份)]＊ 0.1 %
B28: 3 | C28: 過戶代書費:約新台幣18000元,若需辦理貸款, 毎筆設定代書費3000元,設定規費及火險費依實際發生單據支付
B30: 4 | C30: 地價稅:依最近一年稅費概估 ㄧ般稅率之稅費約 | J30: 元
C31: 自用稅率之稅費約 | J31: 元,實際稅額以所核
C32: 發稅單為準,交屋日時依所有權人目前稅額按實際使用比例分算,若遇公告地價調整,另行計算
B33: 5 | C33: 房屋稅:委託人無法即時提供稅單資料,故無法概算(於交屋日依實際使用比例分算)
C34: 住家用按房屋現值 ＊ 1.2%
C35: 營業用按房屋現值 ＊ 3 %
B36: 6 | C36: 水、電、瓦斯費、管理費等雜項費用(於交屋日依實際使用比例分算)
C37: 火險、地震險:若承買人向金融機構貸款始有此項費用,其金額依保險公司費率計算
B38: 7 | C38: 工程受益費:簽約日前已開徵或已開徵未到期(含緩徵)者,由賣方負擔,如未公告則由買方負擔,如已公告未開徵或未到期者應由雙方各負擔二分之ㄧ
B40: 8 | C40: 登記規費(不含書狀費):委託人無法及時提供稅單資料,故無法概算
B41: 9 | C41: 仲介服務費:按實際成交價格的百分之二
B43: 附註:以上買賣雙方支付項目為ㄧ般原則若雙方另以契約約定從其約定

Sheet 秘書-input
A1: 案名: | B1: 西門黃金店面 | C1: 製作物調人員及日期: | D1: 8/5沛蓁 | E1: 審查人員及日期:
A2: 租OR售 | B2: 售
A3: 區域: | B3: 台北市萬華區 | C3: 此格為路/段/巷/弄 | D3: 此格為號樓之幾(正確)
A4: 地址: | B4: 台北市萬華區 | C4: 成都路 | D4: 92號
A5: 製作單位: | B5: 住商仁愛鳳翔加盟店 (願景不動產仲介股份有限公司)
A6: 經紀營業員: | B6: 王馨霈.李宏泉
A7: 主要用途: | B7: (空白) | C7: 請按建物謄本上之主要用途key in
A8: 房屋現況: | B8: 出租
A9: 建物名稱: | B9: 無
A10: 總價: | B10: 7588 | C10: 萬
A11: 建築完成日: | B11: 24015 | C11: =B11 -> 24015 | D11: 屋齡: | E11: =(TODAY()-B11)/365 -> 46.879452 | F11: 年
A12: 主要建材: | B12: 加強磚造
A13: 樓層: | B13: 地上共7層/地下0層;本建物在第1~2層 | D13: 樓層: | E13: 1~2/7F
A14: 格局: | B14: 0/2/2
A15: 座向:
A16: 同層戶數: | C16: 戶
A17: 邊間:
A18: 中庭:
A19: 電梯數:
A20: 建築物管理費: | C20: ,建築物管理費約 | E20: 元/月
A21: 警衛管理:
A22: 學區: | B22: 西門國小 龍山國中
A23: 看屋方式: | B23: 請洽27713366
A24: 瓦斯:
A25: 違建部份: | B25: 無
A26: 交通條件說明: | B26: 近捷運西門站
A27: 空調:
A28: 特利屋物件編號: | B28: 018155
A30: 土地 | B30: 地號: | C30: 漢中段一小段776地號 | D30: 基地面積: | E30: 32 | F30: 平方公尺 | G30: 權利範圍: | H30: 1200 | I30: 分之 | J30: 70 | K30: 使用分區: | L30: 商四 | M30: 建敝率: | N30: 0.75 | O30: 容積率: | P30: 8 | Q30: 基地面積: | R30: =E30*0.3025 -> 9.68 | S30: 坪 | T30: 持分: | U30: =E30*J30/H30 -> 1.8666667 | V30: 平方公尺 | W30: 約 | X30: =U30*0.3025 -> 0.56466667 | Y30: 坪
B31: 地號: | C31: 漢中段一小段779地號 | D31: 基地面積: | E31: 985 | F31: 平方公尺 | G31: 權利範圍: | H31: 10000 | I31: 分之 | J31: =290+290 -> 580 | K31: 使用分區: | L31: 商四 | M31: 建敝率: | N31: 0.75 | O31: 容積率: | P31: 8 | Q31: 基地面積: | R31: =E31*0.3025 -> 297.9625 | S31: 坪 | T31: 持分: | U31: =E31*J31/H31 -> 57.13 | V31: 平方公尺 | W31: 約 | X31: =U31*0.3025 -> 17.281825 | Y31: 坪
B32: 地號: | C32: 漢中段一小段779-0001地號 | D32: 基地面積: | E32: 26 | F32: 平方公尺 | G32: 權利範圍: | H32: 10000 | I32: 分之 | J32: 580 | K32: 使用分區: | L32: 商四 | M32: 建敝率: | N32: 0.75 | O32: 容積率: | P32: 8 | Q32: 基地面積: | R32: =E32*0.3025 -> 7.865 | S32: 坪 | T32: 持分: | U32: =E32*J32/H32 -> 1.508 | V32: 平方公尺 | W32: 約 | X32: =U32*0.3025 -> 0.45617 | Y32: 坪
B33: 地號: | C33: 漢中段一小段780地號 | D33: 基地面積: | E33: 37 | F33: 平方公尺 | G33: 權利範圍: | H33: 10000 | I33: 分之 | J33: 580 | K33: 使用分區: | L33: 商四 | M33: 建敝率: | N33: 0.75 | O33: 容積率: | P33: 8 | Q33: 基地面積: | R33: =E33*0.3025 -> 11.1925 | S33: 坪 | T33: 持分: | U33: =E33*J33/H33 -> 2.146 | V33: 平方公尺 | W33: 約 | X33: =U33*0.3025 -> 0.649165 | Y33: 坪
B34: 地號: | C34: 漢中段一小段780-0001地號 | D34: 基地面積: | E34: 206 | F34: 平方公尺 | G34: 權利範圍: | H34: 10000 | I34: 分之 | J34: 580 | K34: 使用分區: | L34: 商四 | M34: 建敝率: | N34: 0.75 | O34: 容積率: | P34: 8 | Q34: 基地面積: | R34: =E34*0.3025 -> 62.315 | S34: 坪 | T34: 持分: | U34: =E34*J34/H34 -> 11.948 | V34: 平方公尺 | W34: 約 | X34: =U34*0.3025 -> 3.61427 | Y34: 坪
B35: 合計 | E35: =SUM(E31:E34) -> 1254 | F35: 平方公尺 | R35: =SUM(R31:R34) -> 379.335 | S35: 坪 | T35: 持分: | U35: =SUM(U31:U34) -> 72.732 | V35: 平方公尺 | W35: 約 | X35: =SUM(X31:X34) -> 22.00143 | Y35: 坪
A38: 建物 | B38: 建號: | C38: 漢中段一小段257.258建號 | G38: 建物名稱排序如下
B39: 一層: | C39: 42.74 | D39: 平方公尺 | E39: =C39*0.3025 -> 12.92885 | F39: 坪 | G39: 主建物: | J39: =45000*0.22 -> 9900
B40: 二層: | C40: 57.58 | D40: 平方公尺 | E40: =C40*0.3025 -> 17.41795 | F40: 坪 | G40: 陽台/平台/露臺: | J40: 8000
B41: 騎樓: | C41: 14.84 | D41: 平方公尺 | E41: =C41*0.3025 -> 4.4891 | F41: 坪 | G41: 雨遮/花台 | J41: =45000-9900-8000 -> 27100
B42: 其他: | C42: 0 | D42: 平方公尺 | E42: =C42*0.3025 -> 0 | F42: 坪 | G42: 公設 | J42: =27100*0.05 -> 1355
B43: 其他: | C43: 0 | D43: 平方公尺 | E43: =C43*0.3025 -> 0 | F43: 坪 | G43: 地下室 | J43: =J41*0.95 -> 25745
...

Sheet 秘書-注意事項
B3: 一. | C3: 買賣雙方就本標的物買賣事宜,已確知以下事項,並知悉其權利義務:
C4: *樓高六層以上之集合住宅亦屬公眾使用建築物,其中任一樓層室內裝修前均應依「建築法」及「建築物室內裝修管理辦法」有關規定申請審查,並經取得許可文件後, 始得施工。申請方式請檢附圖說等相關文件或委由室內裝修業者向各區縣市政府工務局辦理, 以免受罰。 | F4: *本物件謄本登記之主要用途為空白,使用執照登記為集合住宅,本說明書依使用執照為登錄依據
C5: *主建物面積>112平方公尺,不能辦理國宅貸款。
C6: *本物件建築完成日期係依建築物謄本標示部第 ㄧ次登記日期為準。 | F6: *本物件法定空地之增建物為未經合法建管程序建築之使用範圍,係屬違建,其是否占用鄰地或公共設施用地需辦理土地鑑界方能確定
C7: *本物件頂樓、陽台、天井、平台外推之增建物為未經合法建管程序建築之使用範圍,係屬違建。 | F7: *本物件現況夾層係屬非合法夾層,簽約前須與金融機構確認貸款條件
C8: *主建物面積是否含當層電樓梯間,須比對建築物測量成果圖及實際現況方能確定。 | F8: *本物件經上網查詢台北市政府工務局網站本標的曾被列為違建查報案件。
C9: *建物各項面積合計係依地政機關登記簿謄本登載的面積平方公尺換算為坪所得。(1平方公尺=0.3025坪)，小數點第三位四捨五入取二位)。 | F9: *本物件222地號土地使用分區為第參種住宅區及道路用地（公共設施用地），係道路用地尚未分割，該部份日後將被徵收，若過戶前該部份已辦妥分割並公告徵收禁止移轉，則該部份不列入移轉範圍，但價金是否增減或補償費處理問題，買賣雙方須事先明定。
C10: *本物件成交後辦理產權移轉手續時，若有委託人未提供之土地地號，但地政機關查到所有權人持有同為建築基地之其他筆土地須併同移轉之情形時，委託人應無條件配合辦理，並自行負擔該土地之土地增值稅及其他相關費用。 | F10: *本物件222地號土地使用分區為第參種住宅區及道路用地（公共設施用地），建物是否坐落道路用地，須待申請都市計畫圖方能確定，買賣雙方同意：之後都市計畫圖核發後若建物有坐落公共設施用地，則無條件解除契約。
C11: *建物登記用途請以地政機關辦法為準。
B12: 二 | C12: 買方若欲辦理優惠性貸款（公教、國宅、勞工、首購等）其應具備之資格及條件，由買方自行負責，若因金融機關提供之優惠貸款額度不足時，買方同意依一般利率完成貸款交屋手續。 | F12: *本物件陽台外移、頂樓加蓋之增建物為未經合法建管程序建築之使用範圍，係屬違建；另收定斡旋前須確認所有權人是否有頂樓加蓋使用權，若該加蓋建物有房屋稅籍，則簽約前須出具該房屋稅籍證明，以確認納稅義務人是否為本案所有權人，且過戶時須辦理房屋稅籍更名。
B13: 三 | C13: 買方就承購本標的物若欲供營業用途時，請自行確認是否能辦理公司營業登記等相關事宜。住商不動產不保證買方一定可以辦理工商登記。 | F13: *本物件謄本登記之主要用途與建物測量成果圖及使用執照登記者不符，本不動產說明書以謄本為登錄依據，若須申請優惠購屋貸款，收定前須先確認。
B14: 四 | C14: 增建部份（含頂樓、露台、夾層、一樓空地、平台、一樓圍牆、天井、防火巷、陽台外推、上下樓層打通之內梯等），無所有權，不保證過去沒有被通知拆除或未來不會被拆除及可永久使用，買方已知悉增建所在位置及其權利、義務。 | F14: *本案為土地或二十年以上屋齡之透天厝,買方如欲新建或改建,建議於收訂前徵詢專業建築師之意見;另買方若欲確認土地界址,建議買賣雙方可於過戶前辦理土地鑑界方能確定
B15: 五 | C15: 本案若有頂樓、一樓前後院空地增建者，買方願依原住戶間協議或使用習慣承受。 | F15: *本物件現況之原隔間已拆除，但登記之建物建號未合併。（若分開出售，以下注意事項始須轉載至契據上）本物件現況之原隔間牆已拆除，但登記之建物建號並合併，茲因擬分開出售，故定金需暫存住商不動產仁愛鳳翔店,買賣雙方於收訂前須先約定以下程序所發生費用之分擔方式, 且原共用之設施(如:水電錶、冷熱水管電線等)須恢復個別獨立使用,過戶前所有權人需提供水電、瓦斯單據公確認水電、瓦斯管線是否已為獨立使用:(1)過戶前,需將隔間牆依竣工圖重新隔間(2)若未依竣工圖施作隔間牆,則簽約前須辦竣建物建號合併再分割,並依新分割後謄本登記之建物面積為準,若與原登記面積不符,因此而產生之價差,須於合約中明確訂定價金補貼方式及若無法於約定期限內辦妥建物分割之後續合約履行方式
B16: 六 | C16: 本案買方並未承購停車位者，買方同意依原住戶間協議或大樓管委會規定及住戶規約來使用持分共有地下室、停車空間。 | F16: *本建物因建物謄本未登記建築完成日期,在此以使用執照之發照日期登錄,實際建築完成日期可能在此之前
B17: 七 | C17: 依稅法規定，「先賣後買」或「先買後賣」符合條件者，得向稅捐機關辦理增值稅重購退稅。買賣方如欲辦理退稅時，應自行洽詢稅捐機關以確認資格是否相符，住商不動產不保證一定可以辦理重購退稅。

Sheet 秘書-橫式櫥窗(2格用)
A1: ='秘書-input'!B1 -> 西門黃金店面 | AE1: 照片
U9: 物編: | X9: ='秘書-input'!B28 -> 018155
A10: 總價 | D10: ='秘書-input'!B10 -> 7588 | R10: 萬 | U10: 樓層 | X10: ='秘書-input'!E13 -> 1~2/7F
A15: 坪數 | D15: ='秘書-input'!E46 -> 34.8359 | R15: 坪 | U15: 車位 | X15: ='秘書-input'!C50 -> 無
AE18: 地圖
A20: 格局 | D20: ='秘書-input'!B14 -> 0/2/2 | R20: 屋齡 | U20: ='秘書-input'!E11 -> 46.879452 | AB20: 年
A23: 特 色 | D23: ='秘書-input'!B56
D26: ='秘書-input'!B57
D29: ='秘書-input'!B58
D32: ='秘書-input'!B59
A35: 圓環靜巷頂加 | AE35: 照片
S43: 物編:001997
A44: 總價 | D44: 5500 | R44: 萬 | U44: 樓層 | X44: 7/7F
A49: 坪數 | D49: 54.97 | R49: 坪 | U49: 車位 | X49: 無
AE52: 地圖
A54: 格局 | D54: 4/2/2 | R54: 屋齡 | U54: 33.3 | AB54: 年
A57: 特 色 | D57: 1.雙仁愛學區燙金地段
D60: 2.生活機能完善
D63: 3.雙併住戶單純水準高
D66: 4.陽台外推使用

Sheet 秘書-橫式櫥窗
A1: ='秘書-input'!B1 -> 西門黃金店面
AV12: 物編: | AY12: ='秘書-input'!B28 -> 018155
A13: 總價 | D13: ='秘書-input'!B10 -> 7588 | AE13: 萬 | AH13: 坪數 | AK13: ='秘書-input'!E46 -> 34.8359 | BC13: 坪
A18: 格局 | D18: ='秘書-input'!B14 -> 0/2/2 | U18: 車位 | X18: ='秘書-input'!C50 -> 無 | AE18: 樓層 | AH18: ='秘書-input'!E13 -> 1~2/7F | AO18: 屋齡 | AR18: ='秘書-input'!E11 -> 46.879452 | BC18: 年
A23: 特 色 | D23: ='秘書-input'!B56
D26: ='秘書-input'!B57
D29: ='秘書-input'!B58
D32: ='秘書-input'!B59
A35: 照片 | AC35: 照片
A52: 照片 | AC52: 地圖
